Workbook

Sheet Image_Rename
A1: NO | B1: PANEL DATA | C1: AREA | D1: Attribute | E1: File Path (Insert Your File Path Here) | F1: Current Image File | G1: New Image File | H1: Paste this on bat file
A2: 1 | B2: Overview 33 | C2: OVERVIEW FRONT (LHS) | D2: VISUAL IMAGE | F2: =IF(E2="", "", TRIM(RIGHT(SUBSTITUTE(E2, "\", REPT(" ", LEN(E2))), LEN(E2)))) | G2: 1.jpg | H2: ="ren """ & F2 & """ """ & G2 & """" -> ren "" "1.jpg"
A3: 2 | B3: Overview 33 | C3: OVERVIEW FRONT (LHS) | D3: IR IMAGE | F3: =IF(E3="", "", TRIM(RIGHT(SUBSTITUTE(E3, "\", REPT(" ", LEN(E3))), LEN(E3)))) | G3: 2.jpg | H3: ="ren """ & F3 & """ """ & G3 & """" -> ren "" "2.jpg"
A4: 3 | B4: Overview 33 | C4: OVERVIEW FRONT (RHS) | D4: VISUAL IMAGE | F4: =IF(E4="", "", TRIM(RIGHT(SUBSTITUTE(E4, "\", REPT(" ", LEN(E4))), LEN(E4)))) | G4: 3.jpg | H4: ="ren """ & F4 & """ """ & G4 & """" -> ren "" "3.jpg"
A5: 4 | B5: Overview 33 | C5: OVERVIEW FRONT (RHS) | D5: IR IMAGE | F5: =IF(E5="", "", TRIM(RIGHT(SUBSTITUTE(E5, "\", REPT(" ", LEN(E5))), LEN(E5)))) | G5: 4.jpg | H5: ="ren """ & F5 & """ """ & G5 & """" -> ren "" "4.jpg"
A6: 5 | B6: Overview 33 | C6: OVERVIEW REAR (LHS) | D6: VISUAL IMAGE | F6: =IF(E6="", "", TRIM(RIGHT(SUBSTITUTE(E6, "\", REPT(" ", LEN(E6))), LEN(E6)))) | G6: 5.jpg | H6: ="ren """ & F6 & """ """ & G6 & """" -> ren "" "5.jpg"
A7: 6 | B7: Overview 33 | C7: OVERVIEW REAR (LHS) | D7: IR IMAGE | F7: =IF(E7="", "", TRIM(RIGHT(SUBSTITUTE(E7, "\", REPT(" ", LEN(E7))), LEN(E7)))) | G7: 6.jpg | H7: ="ren """ & F7 & """ """ & G7 & """" -> ren "" "6.jpg"
A8: 7 | B8: Overview 33 | C8: OVERVIEW REAR (RHS) | D8: VISUAL IMAGE | F8: =IF(E8="", "", TRIM(RIGHT(SUBSTITUTE(E8, "\", REPT(" ", LEN(E8))), LEN(E8)))) | G8: 7.jpg | H8: ="ren """ & F8 & """ """ & G8 & """" -> ren "" "7.jpg"
A9: 8 | B9: Overview 33 | C9: OVERVIEW REAR (RHS) | D9: IR IMAGE | F9: =IF(E9="", "", TRIM(RIGHT(SUBSTITUTE(E9, "\", REPT(" ", LEN(E9))), LEN(E9)))) | G9: 8.jpg | H9: ="ren """ & F9 & """ """ & G9 & """" -> ren "" "8.jpg"
A10: 9 | B10: Overview 33 | C10: OVERVIEW TOP (LHS) | D10: VISUAL IMAGE | F10: =IF(E10="", "", TRIM(RIGHT(SUBSTITUTE(E10, "\", REPT(" ", LEN(E10))), LEN(E10)))) | G10: 9.jpg | H10: ="ren """ & F10 & """ """ & G10 & """" -> ren "" "9.jpg"
A11: 10 | B11: Overview 33 | C11: OVERVIEW TOP (LHS) | D11: IR IMAGE | F11: =IF(E11="", "", TRIM(RIGHT(SUBSTITUTE(E11, "\", REPT(" ", LEN(E11))), LEN(E11)))) | G11: 10.jpg | H11: ="ren """ & F11 & """ """ & G11 & """" -> ren "" "10.jpg"
A12: 11 | B12: Overview 33 | C12: OVERVIEW TOP (RHS) | D12: VISUAL IMAGE | F12: =IF(E12="", "", TRIM(RIGHT(SUBSTITUTE(E12, "\", REPT(" ", LEN(E12))), LEN(E12)))) | G12: 11.jpg | H12: ="ren """ & F12 & """ """ & G12 & """" -> ren "" "11.jpg"
A13: 12 | B13: Overview 33 | C13: OVERVIEW TOP (RHS) | D13: IR IMAGE | F13: =IF(E13="", "", TRIM(RIGHT(SUBSTITUTE(E13, "\", REPT(" ", LEN(E13))), LEN(E13)))) | G13: 12.jpg | H13: ="ren """ & F13 & """ """ & G13 & """" -> ren "" "12.jpg"
... A905: 904 | B905: N.E.R | C905: OVERVIEW (LHS) | D905: IR IMAGE | F905: =IF(E905="", "", TRIM(RIGHT(SUBSTITUTE(E905, "\", REPT(" ", LEN(E905))), LEN(E905)))) | G905: 1556.jpg | H905: ="ren """ & F905 & """ """ & G905 & """" -> ren "" "1556.jpg"
A906: 905
A907: 906

Sheet Sheet1
A1: NO | B1: PANEL DATA | C1: AREA | D1: Attribute | E1: File Path (Insert Your File Path Here) | F1: Current Image File | G1: New Image File | H1: Paste this on bat file
A2: 1 | B2: Overview | C2: OVERVIEW | D2: VISUAL IMAGE | F2: =IF(E2="", "", TRIM(RIGHT(SUBSTITUTE(E2, "\", REPT(" ", LEN(E2))), LEN(E2)))) | G2: 1.jpg | H2: ="ren """ & F2 & """ """ & G2 & """" -> ren "" "1.jpg" | K2: Overview | L2: OVERVIEW | M2: 1.jpg
A3: 2 | B3: Overview | C3: OVERVIEW | D3: IR IMAGE | F3: =IF(E3="", "", TRIM(RIGHT(SUBSTITUTE(E3, "\", REPT(" ", LEN(E3))), LEN(E3)))) | G3: 2.jpg | H3: ="ren """ & F3 & """ """ & G3 & """" -> ren "" "2.jpg" | K3: Overview | L3: OVERVIEW | M3: 2.jpg
A4: 3 | B4: Overview | C4: OVERVIEW TOP | D4: VISUAL IMAGE | F4: =IF(E4="", "", TRIM(RIGHT(SUBSTITUTE(E4, "\", REPT(" ", LEN(E4))), LEN(E4)))) | G4: 3.jpg | H4: ="ren """ & F4 & """ """ & G4 & """" -> ren "" "3.jpg" | K4: Overview | L4: OVERVIEW TOP | M4: 3.jpg
A5: 4 | B5: Overview | C5: OVERVIEW TOP | D5: IR IMAGE | F5: =IF(E5="", "", TRIM(RIGHT(SUBSTITUTE(E5, "\", REPT(" ", LEN(E5))), LEN(E5)))) | G5: 4.jpg | H5: ="ren """ & F5 & """ """ & G5 & """" -> ren "" "4.jpg" | K5: Overview | L5: OVERVIEW TOP | M5: 4.jpg
A6: 5 | B6: Overview | C6: OVERVIEW BOTTOM | D6: VISUAL IMAGE | F6: =IF(E6="", "", TRIM(RIGHT(SUBSTITUTE(E6, "\", REPT(" ", LEN(E6))), LEN(E6)))) | G6: 5.jpg | H6: ="ren """ & F6 & """ """ & G6 & """" -> ren "" "5.jpg" | K6: Overview | L6: OVERVIEW BOTTOM | M6: 5.jpg
A7: 6 | B7: Overview | C7: OVERVIEW BOTTOM | D7: IR IMAGE | F7: =IF(E7="", "", TRIM(RIGHT(SUBSTITUTE(E7, "\", REPT(" ", LEN(E7))), LEN(E7)))) | G7: 6.jpg | H7: ="ren """ & F7 & """ """ & G7 & """" -> ren "" "6.jpg" | K7: Overview | L7: OVERVIEW BOTTOM | M7: 6.jpg
A8: 7 | B8: Overview | C8: OVERVIEW REAR | D8: VISUAL IMAGE | F8: =IF(E8="", "", TRIM(RIGHT(SUBSTITUTE(E8, "\", REPT(" ", LEN(E8))), LEN(E8)))) | G8: 7.jpg | H8: ="ren """ & F8 & """ """ & G8 & """" -> ren "" "7.jpg" | K8: Overview | L8: OVERVIEW REAR | M8: 7.jpg
A9: 8 | B9: Overview | C9: OVERVIEW REAR | D9: IR IMAGE | F9: =IF(E9="", "", TRIM(RIGHT(SUBSTITUTE(E9, "\", REPT(" ", LEN(E9))), LEN(E9)))) | G9: 8.jpg | H9: ="ren """ & F9 & """ """ & G9 & """" -> ren "" "8.jpg" | K9: Overview | L9: OVERVIEW REAR | M9: 8.jpg
A10: 9 | B10: Overview | C10: OVERVIEW SIDE (LHS) | D10: VISUAL IMAGE | F10: =IF(E10="", "", TRIM(RIGHT(SUBSTITUTE(E10, "\", REPT(" ", LEN(E10))), LEN(E10)))) | G10: 9.jpg | H10: ="ren """ & F10 & """ """ & G10 & """" -> ren "" "9.jpg" | K10: Overview | L10: OVERVIEW SIDE (LHS) | M10: 9.jpg
A11: 10 | B11: Overview | C11: OVERVIEW SIDE (LHS) | D11: IR IMAGE | F11: =IF(E11="", "", TRIM(RIGHT(SUBSTITUTE(E11, "\", REPT(" ", LEN(E11))), LEN(E11)))) | G11: 10.jpg | H11: ="ren """ & F11 & """ """ & G11 & """" -> ren "" "10.jpg" | K11: Overview | L11: OVERVIEW SIDE (LHS) | M11: 10.jpg
A12: 11 | B12: Overview | C12: OVERVIEW SIDE (RHS) | D12: VISUAL IMAGE | F12: =IF(E12="", "", TRIM(RIGHT(SUBSTITUTE(E12, "\", REPT(" ", LEN(E12))), LEN(E12)))) | G12: 11.jpg | H12: ="ren """ & F12 & """ """ & G12 & """" -> ren "" "11.jpg" | K12: Overview | L12: OVERVIEW SIDE (RHS) | M12: 11.jpg
A13: 12 | B13: Overview | C13: OVERVIEW SIDE (RHS) | D13: IR IMAGE | F13: =IF(E13="", "", TRIM(RIGHT(SUBSTITUTE(E13, "\", REPT(" ", LEN(E13))), LEN(E13)))) | G13: 12.jpg | H13: ="ren """ & F13 & """ """ & G13 & """" -> ren "" "12.jpg" | K13: Overview | L13: OVERVIEW SIDE (RHS) | M13: 12.jpg
... A101: 100 | B101: BATTERY BANK 4 | C101: OVERVIEW | D101: IR IMAGE | F101: =IF(E101="", "", TRIM(RIGHT(SUBSTITUTE(E101, "\", REPT(" ", LEN(E101))), LEN(E101)))) | G101: 100.jpg | H101: ="ren """ & F101 & """ """ & G101 & """" -> ren "" "100.jpg" | K101: BATTERY BANK 4 | L101: OVERVIEW | M101: 100.jpg

Sheet Image_Rename_VCB
A1: NO | B1: PANEL DATA | C1: AREA | E1: Attribute | F1: File Path (Insert Your File Path Here) | G1: Current Image File | H1: New Image File | I1: Paste this on bat file
A2: 25 | B2: Panel1 | C2: BREAKER COMPARTMENT | E2: VISUAL IMAGE | F2: C:\Users\aremi\Desktop\REPORT CBM\PO 42234207 - JOHOR - JBU - 400 PE IR US TEV\03. RAW MATERIAL\118. 18072026 MASJID KOTA ISKANDAR\IR\FLIR0173- photo.jpg | G2: =IF(F2="", "", TRIM(RIGHT(SUBSTITUTE(F2, "\", REPT(" ", LEN(F2))), LEN(F2)))) -> FLIR0173- photo.jpg | H2: 25.jpg | I2: ="ren """ & G2 & """ """ & H2 & """" -> ren "FLIR0173- photo.jpg" "25.jpg"
A3: 26 | B3: Panel1 | C3: BREAKER COMPARTMENT | E3: IR IMAGE | F3: C:\Users\aremi\Desktop\REPORT CBM\PO 42234207 - JOHOR - JBU - 400 PE IR US TEV\03. RAW MATERIAL\118. 18072026 MASJID KOTA ISKANDAR\IR\FLIR0173.jpg | G3: =IF(F3="", "", TRIM(RIGHT(SUBSTITUTE(F3, "\", REPT(" ", LEN(F3))), LEN(F3)))) -> FLIR0173.jpg | H3: 26.jpg | I3: ="ren """ & G3 & """ """ & H3 & """" -> ren "FLIR0173.jpg" "26.jpg"
A4: 41 | B4: Panel2 | C4: BREAKER COMPARTMENT | E4: VISUAL IMAGE | F4: C:\Users\aremi\Desktop\REPORT CBM\PO 42234207 - JOHOR - JBU - 400 PE IR US TEV\03. RAW MATERIAL\118. 18072026 MASJID KOTA ISKANDAR\IR\FLIR0174- photo.jpg | G4: =IF(F4="", "", TRIM(RIGHT(SUBSTITUTE(F4, "\", REPT(" ", LEN(F4))), LEN(F4)))) -> FLIR0174- photo.jpg | H4: 41.jpg | I4: ="ren """ & G4 & """ """ & H4 & """" -> ren "FLIR0174- photo.jpg" "41.jpg"
A5: 42 | B5: Panel2 | C5: BREAKER COMPARTMENT | E5: IR IMAGE | F5: C:\Users\aremi\Desktop\REPORT CBM\PO 42234207 - JOHOR - JBU - 400 PE IR US TEV\03. RAW MATERIAL\118. 18072026 MASJID KOTA ISKANDAR\IR\FLIR0174.jpg | G5: =IF(F5="", "", TRIM(RIGHT(SUBSTITUTE(F5, "\", REPT(" ", LEN(F5))), LEN(F5)))) -> FLIR0174.jpg | H5: 42.jpg | I5: ="ren """ & G5 & """ """ & H5 & """" -> ren "FLIR0174.jpg" "42.jpg"
A6: 57 | B6: Panel3 | C6: BREAKER COMPARTMENT | E6: VISUAL IMAGE | F6: C:\Users\aremi\Desktop\REPORT CBM\PO 42234207 - JOHOR - JBU - 400 PE IR US TEV\03. RAW MATERIAL\118. 18072026 MASJID KOTA ISKANDAR\IR\FLIR0175- photo.jpg | G6: =IF(F6="", "", TRIM(RIGHT(SUBSTITUTE(F6, "\", REPT(" ", LEN(F6))), LEN(F6)))) -> FLIR0175- photo.jpg | H6: 57.jpg | I6: ="ren """ & G6 & """ """ & H6 & """" -> ren "FLIR0175- photo.jpg" "57.jpg"
A7: 58 | B7: Panel3 | C7: BREAKER COMPARTMENT | E7: IR IMAGE | F7: C:\Users\aremi\Desktop\REPORT CBM\PO 42234207 - JOHOR - JBU - 400 PE IR US TEV\03. RAW MATERIAL\118. 18072026 MASJID KOTA ISKANDAR\IR\FLIR0175.jpg | G7: =IF(F7="", "", TRIM(RIGHT(SUBSTITUTE(F7, "\", REPT(" ", LEN(F7))), LEN(F7)))) -> FLIR0175.jpg | H7: 58.jpg | I7: ="ren """ & G7 & """ """ & H7 & """" -> ren "FLIR0175.jpg" "58.jpg"
A8: 73 | B8: Panel4 | C8: BREAKER COMPARTMENT | E8: VISUAL IMAGE | G8: =IF(F8="", "", TRIM(RIGHT(SUBSTITUTE(F8, "\", REPT(" ", LEN(F8))), LEN(F8)))) | H8: 73.jpg | I8: ="ren """ & G8 & """ """ & H8 & """" -> ren "" "73.jpg"
A9: 74 | B9: Panel4 | C9: BREAKER COMPARTMENT | E9: IR IMAGE | G9: =IF(F9="", "", TRIM(RIGHT(SUBSTITUTE(F9, "\", REPT(" ", LEN(F9))), LEN(F9)))) | H9: 74.jpg | I9: ="ren """ & G9 & """ """ & H9 & """" -> ren "" "74.jpg"
A10: 89 | B10: Panel5 | C10: BREAKER COMPARTMENT | E10: VISUAL IMAGE | G10: =IF(F10="", "", TRIM(RIGHT(SUBSTITUTE(F10, "\", REPT(" ", LEN(F10))), LEN(F10)))) | H10: 89.jpg | I10: ="ren """ & G10 & """ """ & H10 & """" -> ren "" "89.jpg"
A11: 90 | B11: Panel5 | C11: BREAKER COMPARTMENT | E11: IR IMAGE | G11: =IF(F11="", "", TRIM(RIGHT(SUBSTITUTE(F11, "\", REPT(" ", LEN(F11))), LEN(F11)))) | H11: 90.jpg | I11: ="ren """ & G11 & """ """ & H11 & """" -> ren "" "90.jpg"
A12: 105 | B12: Panel6 | C12: BREAKER COMPARTMENT | E12: VISUAL IMAGE | G12: =IF(F12="", "", TRIM(RIGHT(SUBSTITUTE(F12, "\", REPT(" ", LEN(F12))), LEN(F12)))) | H12: 105.jpg | I12: ="ren """ & G12 & """ """ & H12 & """" -> ren "" "105.jpg"
A13: 106 | B13: Panel6 | C13: BREAKER COMPARTMENT | E13: IR IMAGE | G13: =IF(F13="", "", TRIM(RIGHT(SUBSTITUTE(F13, "\", REPT(" ", LEN(F13))), LEN(F13)))) | H13: 106.jpg | I13: ="ren """ & G13 & """ """ & H13 & """" -> ren "" "106.jpg"
A14: 121 | B14: Panel7 | C14: BREAKER COMPARTMENT | E14: VISUAL IMAGE | G14: =IF(F14="", "", TRIM(RIGHT(SUBSTITUTE(F14, "\", REPT(" ", LEN(F14))), LEN(F14)))) | H14: 121.jpg | I14: ="ren """ & G14 & """ """ & H14 & """" -> ren "" "121.jpg"
A15: 122 | B15: Panel7 | C15: BREAKER COMPARTMENT | E15: IR IMAGE | G15: =IF(F15="", "", TRIM(RIGHT(SUBSTITUTE(F15, "\", REPT(" ", LEN(F15))), LEN(F15)))) | H15: 122.jpg | I15: ="ren """ & G15 & """ """ & H15 & """" -> ren "" "122.jpg"
A16: 137 | B16: Panel8 | C16: BREAKER COMPARTMENT | E16: VISUAL IMAGE | G16: =IF(F16="", "", TRIM(RIGHT(SUBSTITUTE(F16, "\", REPT(" ", LEN(F16))), LEN(F16)))) | H16: 137.jpg | I16: ="ren """ & G16 & """ """ & H16 & """" -> ren "" "137.jpg"
A17: 138 | B17: Panel8 | C17: BREAKER COMPARTMENT | E17: IR IMAGE | G17: =IF(F17="", "", TRIM(RIGHT(SUBSTITUTE(F17, "\", REPT(" ", LEN(F17))), LEN(F17)))) | H17: 138.jpg | I17: ="ren """ & G17 & """ """ & H17 & """" -> ren "" "138.jpg"
A18: 153 | B18: Panel9 | C18: BREAKER COMPARTMENT | E18: VISUAL IMAGE | G18: =IF(F18="", "", TRIM(RIGHT(SUBSTITUTE(F18, "\", REPT(" ", LEN(F18))), LEN(F18)))) | H18: 153.jpg | I18: ="ren """ & G18 & """ """ & H18 & """" -> ren "" "153.jpg"
A19: 154 | B19: Panel9 | C19: BREAKER COMPARTMENT | E19: IR IMAGE | G19: =IF(F19="", "", TRIM(RIGHT(SUBSTITUTE(F19, "\", REPT(" ", LEN(F19))), LEN(F19)))) | H19: 154.jpg | I19: ="ren """ & G19 & """ """ & H19 & """" -> ren "" "154.jpg"
... A31: 250 | B31: Panel15 | C31: BREAKER COMPARTMENT | E31: IR IMAGE | G31: =IF(F31="", "", TRIM(RIGHT(SUBSTITUTE(F31, "\", REPT(" ", LEN(F31))), LEN(F31)))) | H31: 250.jpg | I31: ="ren """ & G31 & """ """ & H31 & """" -> ren "" "250.jpg"
A32: 31 | B32: Panel1 | C32: BUSBAR COMPARTMENT | E32: VISUAL IMAGE | F32: C:\Users\aremi\Desktop\REPORT CBM\PO 42234207 - JOHOR - JBU - 400 PE IR US TEV\03. RAW MATERIAL\118. 18072026 MASJID KOTA ISKANDAR\IR\FLIR0181- photo.jpg | G32: =IF(F32="", "", TRIM(RIGHT(SUBSTITUTE(F32, "\", REPT(" ", LEN(F32))), LEN(F32)))) -> FLIR0181- photo.jpg | H32: 31.jpg | I32: ="ren """ & G32 & """ """ & H32 & """" -> ren "FLIR0181- photo.jpg" "31.jpg" | K32: C:\Users\aremi\Desktop\REPORT CBM\PO 42289580 - Pahang 11kV SECOND CYCLE AZZAD 2026\RAW MATERIAL\001. SSU CHEROH (VI)\RAW DATA\IR\New folder\FLIR_0030- photo.jpg
A33: 32 | B33: Panel1 | C33: BUSBAR COMPARTMENT | E33: IR IMAGE | F33: C:\Users\aremi\Desktop\REPORT CBM\PO 42234207 - JOHOR - JBU - 400 PE IR US TEV\03. RAW MATERIAL\118. 18072026 MASJID KOTA ISKANDAR\IR\FLIR0181.jpg | G33: =IF(F33="", "", TRIM(RIGHT(SUBSTITUTE(F33, "\", REPT(" ", LEN(F33))), LEN(F33)))) -> FLIR0181.jpg | H33: 32.jpg | I33: ="ren """ & G33 & """ """ & H33 & """" -> ren "FLIR0181.jpg" "32.jpg" | K33: C:\Users\aremi\Desktop\REPORT CBM\PO 42289580 - Pahang 11kV SECOND CYCLE AZZAD 2026\RAW MATERIAL\001. SSU CHEROH (VI)\RAW DATA\IR\New folder\FLIR_0030.jpg
A34: 47 | B34: Panel2 | C34: BUSBAR COMPARTMENT | E34: VISUAL IMAGE | F34: C:\Users\aremi\Desktop\REPORT CBM\PO 42234207 - JOHOR - JBU - 400 PE IR US TEV\03. RAW MATERIAL\118. 18072026 MASJID KOTA ISKANDAR\IR\FLIR0182- photo.jpg | G34: =IF(F34="", "", TRIM(RIGHT(SUBSTITUTE(F34, "\", REPT(" ", LEN(F34))), LEN(F34)))) -> FLIR0182- photo.jpg | H34: 47.jpg | I34: ="ren """ & G34 & """ """ & H34 & """" -> ren "FLIR0182- photo.jpg" "47.jpg" | K34: C:\Users\aremi\Desktop\REPORT CBM\PO 42289580 - Pahang 11kV SECOND CYCLE AZZAD 2026\RAW MATERIAL\001. SSU CHEROH (VI)\RAW DATA\IR\New folder\FLIR_0031- photo.jpg
A35: 48 | B35: Panel2 | C35: BUSBAR COMPARTMENT | E35: IR IMAGE | F35: C:\Users\aremi\Desktop\REPORT CBM\PO 42234207 - JOHOR - JBU - 400 PE IR US TEV\03. RAW MATERIAL\118. 18072026 MASJID KOTA ISKANDAR\IR\FLIR0182.jpg | G35: =IF(F35="", "", TRIM(RIGHT(SUBSTITUTE(F35, "\", REPT(" ", LEN(F35))), LEN(F35)))) -> FLIR0182.jpg | H35: 48.jpg | I35: ="ren """ & G35 & """ """ & H35 & """" -> ren "FLIR0182.jpg" "48.jpg" | K35: C:\Users\aremi\Desktop\REPORT CBM\PO 42289580 - Pahang 11kV SECOND CYCLE AZZAD 2026\RAW MATERIAL\001. SSU CHEROH (VI)\RAW DATA\IR\New folder\FLIR_0031.jpg
A36: 63 | B36: Panel3 | C36: BUSBAR COMPARTMENT | E36: VISUAL IMAGE | F36: C:\Users\aremi\Desktop\REPORT CBM\PO 42234207 - JOHOR - JBU - 400 PE IR US TEV\03. RAW MATERIAL\118. 18072026 MASJID KOTA ISKANDAR\IR\FLIR0183- photo.jpg | G36: =IF(F36="", "", TRIM(RIGHT(SUBSTITUTE(F36, "\", REPT(" ", LEN(F36))), LEN(F36)))) -> FLIR0183- photo.jpg | H36: 63.jpg | I36: ="ren """ & G36 & """ """ & H36 & """" -> ren "FLIR0183- photo.jpg" "63.jpg" | K36: C:\Users\aremi\Desktop\REPORT CBM\PO 42289580 - Pahang 11kV SECOND CYCLE AZZAD 2026\RAW MATERIAL\001. SSU CHEROH (VI)\RAW DATA\IR\New folder\FLIR_0032- photo.jpg
A37: 64 | B37: Panel3 | C37: BUSBAR COMPARTMENT | E37: IR IMAGE | F37: C:\Users\aremi\Desktop\REPORT CBM\PO 42234207 - JOHOR - JBU - 400 PE IR US TEV\03. RAW MATERIAL\118. 18072026 MASJID KOTA ISKANDAR\IR\FLIR0183.jpg | G37: =IF(F37="", "", TRIM(RIGHT(SUBSTITUTE(F37, "\", REPT(" ", LEN(F37))), LEN(F37)))) -> FLIR0183.jpg | H37: 64.jpg | I37: ="ren """ & G37 & """ """ & H37 & """" -> ren "FLIR0183.jpg" "64.jpg" | K37: C:\Users\aremi\Desktop\REPORT CBM\PO 42289580 - Pahang 11kV SECOND CYCLE AZZAD 2026\RAW MATERIAL\001. SSU CHEROH (VI)\RAW DATA\IR\New folder\FLIR_0032.jpg
A38: 79 | B38: Panel4 | C38: BUSBAR COMPARTMENT | E38: VISUAL IMAGE | G38: =IF(F38="", "", TRIM(RIGHT(SUBSTITUTE(F38, "\", REPT(" ", LEN(F38))), LEN(F38)))) | H38: 79.jpg | I38: ="ren """ & G38 & """ """ & H38 & """" -> ren "" "79.jpg" | K38: C:\Users\aremi\Desktop\REPORT CBM\PO 42289580 - Pahang 11kV SECOND CYCLE AZZAD 2026\RAW MATERIAL\001. SSU CHEROH (VI)\RAW DATA\IR\New folder\FLIR_0033- photo.jpg
A39: 80 | B39: Panel4 | C39: BUSBAR COMPARTMENT | E39: IR IMAGE | G39: =IF(F39="", "", TRIM(RIGHT(SUBSTITUTE(F39, "\", REPT(" ", LEN(F39))), LEN(F39)))) | H39: 80.jpg | I39: ="ren """ & G39 & """ """ & H39 & """" -> ren "" "80.jpg" | K39: C:\Users\aremi\Desktop\REPORT CBM\PO 42289580 - Pahang 11kV SECOND CYCLE AZZAD 2026\RAW MATERIAL\001. SSU CHEROH (VI)\RAW DATA\IR\New folder\FLIR_0033.jpg
A40: 95 | B40: Panel5 | C40: BUSBAR COMPARTMENT | E40: VISUAL IMAGE | G40: =IF(F40="", "", TRIM(RIGHT(SUBSTITUTE(F40, "\", REPT(" ", LEN(F40))), LEN(F40)))) | H40: 95.jpg | I40: ="ren """ & G40 & """ """ & H40 & """" -> ren "" "95.jpg" | K40: C:\Users\aremi\Desktop\REPORT CBM\PO 42289580 - Pahang 11kV SECOND CYCLE AZZAD 2026\RAW MATERIAL\001. SSU CHEROH (VI)\RAW DATA\IR\New folder\FLIR_0034- photo.jpg
A41: 96 | B41: Panel5 | C41: BUSBAR COMPARTMENT | E41: IR IMAGE | G41: =IF(F41="", "", TRIM(RIGHT(SUBSTITUTE(F41, "\", REPT(" ", LEN(F41))), LEN(F41)))) | H41: 96.jpg | I41: ="ren """ & G41 & """ """ & H41 & """" -> ren "" "96.jpg" | K41: C:\Users\aremi\Desktop\REPORT CBM\PO 42289580 - Pahang 11kV SECOND CYCLE AZZAD 2026\RAW MATERIAL\001. SSU CHEROH (VI)\RAW DATA\IR\New folder\FLIR_0034.jpg
A42: 111 | B42: Panel6 | C42: BUSBAR COMPARTMENT | E42: VISUAL IMAGE | G42: =IF(F42="", "", TRIM(RIGHT(SUBSTITUTE(F42, "\", REPT(" ", LEN(F42))), LEN(F42)))) | H42: 111.jpg | I42: ="ren """ & G42 & """ """ & H42 & """" -> ren "" "111.jpg" | K42: C:\Users\aremi\Desktop\REPORT CBM\PO 42289580 - Pahang 11kV SECOND CYCLE AZZAD 2026\RAW MATERIAL\001. SSU CHEROH (VI)\RAW DATA\IR\New folder\FLIR_0035- photo.jpg
A43: 112 | B43: Panel6 | C43: BUSBAR COMPARTMENT | E43: IR IMAGE | G43: =IF(F43="", "", TRIM(RIGHT(SUBSTITUTE(F43, "\", REPT(" ", LEN(F43))), LEN(F43)))) | H43: 112.jpg | I43: ="ren """ & G43 & """ """ & H43 & """" -> ren "" "112.jpg" | K43: C:\Users\aremi\Desktop\REPORT CBM\PO 42289580 - Pahang 11kV SECOND CYCLE AZZAD 2026\RAW MATERIAL\001. SSU CHEROH (VI)\RAW DATA\IR\New folder\FLIR_0035.jpg
A44: 127 | B44: Panel7 | C44: BUSBAR COMPARTMENT | E44: VISUAL IMAGE | G44: =IF(F44="", "", TRIM(RIGHT(SUBSTITUTE(F44, "\", REPT(" ", LEN(F44))), LEN(F44)))) | H44: 127.jpg | I44: ="ren """ & G44 & """ """ & H44 & """" -> ren "" "127.jpg" | K44: C:\Users\aremi\Desktop\REPORT CBM\PO 42289580 - Pahang 11kV SECOND CYCLE AZZAD 2026\RAW MATERIAL\001. SSU CHEROH (VI)\RAW DATA\IR\New folder\FLIR_0036- photo.jpg
A45: 128 | B45: Panel7 | C45: BUSBAR COMPARTMENT | E45: IR IMAGE | G45: =IF(F45="", "", TRIM(RIGHT(SUBSTITUTE(F45, "\", REPT(" ", LEN(F45))), LEN(F45)))) | H45: 128.jpg | I45: ="ren """ & G45 & """ """ & H45 & """" -> ren "" "128.jpg" | K45: C:\Users\aremi\Desktop\REPORT CBM\PO 42289580 - Pahang 11kV SECOND CYCLE AZZAD 2026\RAW MATERIAL\001. SSU CHEROH (VI)\RAW DATA\IR\New folder\FLIR_0036.jpg
A46: 143 | B46: Panel8 | C46: BUSBAR COMPARTMENT | E46: VISUAL IMAGE | G46: =IF(F46="", "", TRIM(RIGHT(SUBSTITUTE(F46, "\", REPT(" ", LEN(F46))), LEN(F46)))) | H46: 143.jpg | I46: ="ren """ & G46 & """ """ & H46 & """" -> ren "" "143.jpg" | K46: C:\Users\aremi\Desktop\REPORT CBM\PO 42289580 - Pahang 11kV SECOND CYCLE AZZAD 2026\RAW MATERIAL\001. SSU CHEROH (VI)\RAW DATA\IR\FLIR_0037- photo.jpg
A47: 144 | B47: Panel8 | C47: BUSBAR COMPARTMENT | E47: IR IMAGE | G47: =IF(F47="", "", TRIM(RIGHT(SUBSTITUTE(F47, "\", REPT(" ", LEN(F47))), LEN(F47)))) | H47: 144.jpg | I47: ="ren """ & G47 & """ """ & H47 & """" -> ren "" "144.jpg" | K47: C:\Users\aremi\Desktop\REPORT CBM\PO 42289580 - Pahang 11kV SECOND CYCLE AZZAD 2026\RAW MATERIAL\001. SSU CHEROH (VI)\RAW DATA\IR\FLIR_0037.jpg
A48: 159 | B48: Panel9 | C48: BUSBAR COMPARTMENT | E48: VISUAL IMAGE | G48: =IF(F48="", "", TRIM(RIGHT(SUBSTITUTE(F48, "\", REPT(" ", LEN(F48))), LEN(F48)))) | H48: 159.jpg | I48: ="ren """ & G48 & """ """ & H48 & """" -> ren "" "159.jpg"
A49: 160 | B49: Panel9 | C49: BUSBAR COMPARTMENT | E49: IR IMAGE | G49: =IF(F49="", "", TRIM(RIGHT(SUBSTITUTE(F49, "\", REPT(" ", LEN(F49))), LEN(F49)))) | H49: 160.jpg | I49: ="ren """ & G49 & """ """ & H49 & """" -> ren "" "160.jpg"
A50: 175 | B50: Panel10 | C50: BUSBAR COMPARTMENT | E50: VISUAL IMAGE | G50: =IF(F50="", "", TRIM(RIGHT(SUBSTITUTE(F50, "\", REPT(" ", LEN(F50))), LEN(F50)))) | H50: 175.jpg | I50: ="ren """ & G50 & """ """ & H50 & """" -> ren "" "175.jpg"
A51: 176 | B51: Panel10 | C51: BUSBAR COMPARTMENT | E51: IR IMAGE | G51: =IF(F51="", "", TRIM(RIGHT(SUBSTITUTE(F51, "\", REPT(" ", LEN(F51))), LEN(F51)))) | H51: 176.jpg | I51: ="ren """ & G51 & """ """ & H51 & """" -> ren "" "176.jpg"
...

Sheet Image_Rename_RMU
A1: NO | B1: PANEL DATA | C1: AREA | D1: Attribute | E1: File Path (Insert Your File Path Here) | F1: Current Image File | G1: New Image File | H1: Paste this on bat file
A2: 1 | B2: Overview | C2: OVERVIEW | D2: VISUAL IMAGE | F2: =IF(E2="", "", TRIM(RIGHT(SUBSTITUTE(E2, "\", REPT(" ", LEN(E2))), LEN(E2)))) | G2: 1.jpg | H2: ="ren """ & F2 & """ """ & G2 & """" -> ren "" "1.jpg" | K2: Overview | L2: OVERVIEW | M2: 1.jpg
A3: 2 | B3: Overview | C3: OVERVIEW | D3: IR IMAGE | F3: =IF(E3="", "", TRIM(RIGHT(SUBSTITUTE(E3, "\", REPT(" ", LEN(E3))), LEN(E3)))) | G3: 2.jpg | H3: ="ren """ & F3 & """ """ & G3 & """" -> ren "" "2.jpg" | K3: Overview | L3: OVERVIEW | M3: 2.jpg
A4: 3 | B4: Overview | C4: OVERVIEW TOP | D4: VISUAL IMAGE | F4: =IF(E4="", "", TRIM(RIGHT(SUBSTITUTE(E4, "\", REPT(" ", LEN(E4))), LEN(E4)))) | G4: 3.jpg | H4: ="ren """ & F4 & """ """ & G4 & """" -> ren "" "3.jpg" | K4: Overview | L4: OVERVIEW TOP | M4: 3.jpg
A5: 4 | B5: Overview | C5: OVERVIEW TOP | D5: IR IMAGE | F5: =IF(E5="", "", TRIM(RIGHT(SUBSTITUTE(E5, "\", REPT(" ", LEN(E5))), LEN(E5)))) | G5: 4.jpg | H5: ="ren """ & F5 & """ """ & G5 & """" -> ren "" "4.jpg" | K5: Overview | L5: OVERVIEW TOP | M5: 4.jpg
A6: 5 | B6: Overview | C6: OVERVIEW BOTTOM | D6: VISUAL IMAGE | F6: =IF(E6="", "", TRIM(RIGHT(SUBSTITUTE(E6, "\", REPT(" ", LEN(E6))), LEN(E6)))) | G6: 5.jpg | H6: ="ren """ & F6 & """ """ & G6 & """" -> ren "" "5.jpg" | K6: Overview | L6: OVERVIEW BOTTOM | M6: 5.jpg
A7: 6 | B7: Overview | C7: OVERVIEW BOTTOM | D7: IR IMAGE | F7: =IF(E7="", "", TRIM(RIGHT(SUBSTITUTE(E7, "\", REPT(" ", LEN(E7))), LEN(E7)))) | G7: 6.jpg | H7: ="ren """ & F7 & """ """ & G7 & """" -> ren "" "6.jpg" | K7: Overview | L7: OVERVIEW BOTTOM | M7: 6.jpg
A8: 7 | B8: Overview | C8: OVERVIEW REAR | D8: VISUAL IMAGE | F8: =IF(E8="", "", TRIM(RIGHT(SUBSTITUTE(E8, "\", REPT(" ", LEN(E8))), LEN(E8)))) | G8: 7.jpg | H8: ="ren """ & F8 & """ """ & G8 & """" -> ren "" "7.jpg" | K8: Overview | L8: OVERVIEW REAR | M8: 7.jpg
A9: 8 | B9: Overview | C9: OVERVIEW REAR | D9: IR IMAGE | F9: =IF(E9="", "", TRIM(RIGHT(SUBSTITUTE(E9, "\", REPT(" ", LEN(E9))), LEN(E9)))) | G9: 8.jpg | H9: ="ren """ & F9 & """ """ & G9 & """" -> ren "" "8.jpg" | K9: Overview | L9: OVERVIEW REAR | M9: 8.jpg
A10: 9 | B10: Overview | C10: OVERVIEW SIDE (LHS) | D10: VISUAL IMAGE | F10: =IF(E10="", "", TRIM(RIGHT(SUBSTITUTE(E10, "\", REPT(" ", LEN(E10))), LEN(E10)))) | G10: 9.jpg | H10: ="ren """ & F10 & """ """ & G10 & """" -> ren "" "9.jpg" | K10: Overview | L10: OVERVIEW SIDE (LHS) | M10: 9.jpg
A11: 10 | B11: Overview | C11: OVERVIEW SIDE (LHS) | D11: IR IMAGE | F11: =IF(E11="", "", TRIM(RIGHT(SUBSTITUTE(E11, "\", REPT(" ", LEN(E11))), LEN(E11)))) | G11: 10.jpg | H11: ="ren """ & F11 & """ """ & G11 & """" -> ren "" "10.jpg" | K11: Overview | L11: OVERVIEW SIDE (LHS) | M11: 10.jpg
A12: 11 | B12: Overview | C12: OVERVIEW SIDE (RHS) | D12: VISUAL IMAGE | F12: =IF(E12="", "", TRIM(RIGHT(SUBSTITUTE(E12, "\", REPT(" ", LEN(E12))), LEN(E12)))) | G12: 11.jpg | H12: ="ren """ & F12 & """ """ & G12 & """" -> ren "" "11.jpg" | K12: Overview | L12: OVERVIEW SIDE (RHS) | M12: 11.jpg
A13: 12 | B13: Overview | C13: OVERVIEW SIDE (RHS) | D13: IR IMAGE | F13: =IF(E13="", "", TRIM(RIGHT(SUBSTITUTE(E13, "\", REPT(" ", LEN(E13))), LEN(E13)))) | G13: 12.jpg | H13: ="ren """ & F13 & """ """ & G13 & """" -> ren "" "12.jpg" | K13: Overview | L13: OVERVIEW SIDE (RHS) | M13: 12.jpg
... A101: 100 | B101: BATTERY BANK 4 | C101: OVERVIEW | D101: IR IMAGE | F101: =IF(E101="", "", TRIM(RIGHT(SUBSTITUTE(E101, "\", REPT(" ", LEN(E101))), LEN(E101)))) | G101: 100.jpg | H101: ="ren """ & F101 & """ """ & G101 & """" -> ren "" "100.jpg" | K101: BATTERY BANK 4 | L101: OVERVIEW | M101: 100.jpg

Sheet Image_Mapping_VCB (2)
A1: No | B1: Type | C1: Group | D1: Word Template | E1: Template Page No | F1: {{ substation.name_erms }} | G1: {{ substation.time }} | H1: {{ substation.date }} | I1: {{ substation.ambient }} | J1: {{ substation.humidity }} | K1: {{ swg.area }} | L1: {{ panel.linknumber }} | M1: {{ panel.name }} | N1: {{ panel.cabletype }} | O1: {{ panel.breakerstatus }} | P1: {{ panel.busbarposition }} | Q1: {{ panel.loadamp }} | R1: {{ panel.heateramp }} | S1: {{ swg.serialnumber }} | T1: {{ swg.manufacturer }} | U1: {{ swg.type }} | V1: {{ swg.rating }} | W1: {{ swg.model }} | X1: {{ tx1.manufacturer }} | Y1: {{ tx1.model }} | Z1: {{ tx1.rating }} | AA1: {{ tx1.serialnumber }} | AB1: {{ tx2.manufacturer }} | AC1: {{ tx2.model }} | AD1: {{ tx2.rating }} | AE1: {{ tx2.serialnumber }} | AF1: {{ fp1.manufacturer }} | AG1: {{ fp1.model }} | AH1: {{ fp1.rating }} | AI1: {{ fp1.serialnumber }} | AJ1: {{ fp1.labelsource }} | AK1: {{ fp2.manufacturer }} | AL1: {{ fp2.model }} | AM1: {{ fp2.rating }} | AN1: {{ fp2.serialnumber }} | AO1: {{ fp2.labelsource }} | AP1: {{ batt1.manufacturer }} | AQ1: {{ batt1.model }} | AR1: {{ batt1.serialnumber }} | AS1: {{ batt2.manufacturer }} | AT1: {{ batt2.model }} | AU1: {{ batt2.serialnumber }} | AV1: {{ batt3.manufacturer }} | AW1: {{ batt3.model }} | AX1: {{ batt3.serialnumber }} | AY1: {{ batt4.manufacturer }} | AZ1: {{ batt4.model }} | BA1: {{ batt4.serialnumber }} | BL1: Field Overrides | BM1: Output File Name | BN1: Attribute | BO1: Folder | BP1: New File Path
A2: 1 | B2: Overview 33 | C2: 1 | D2: 01. 33OVERVIEW.docx | E2: 1 | F2: =Master_List!$AW$1 -> PERPUSTAKAAN PUSAT | G2: =Master_List!$AW$2 -> 09:30 PM | H2: =Master_List!$AW$3 -> 20/07/2026 | I2: =Master_List!$AW$4 -> 28.5 | J2: =Master_List!$AW$5 -> 65 | K2: OVERVIEW FRONT (LHS) | BL2: {} | BM2: page1 | BN2: Visual Image Path | BO2: C:\Users\aremi\Desktop\REPORT CBM\PO TIANU JB\03. Raw Material\40. 10052026 SSU MEDINI SIGNATURE 33KV (VI)\IR | BP2: 1.jpg
A3: 1 | B3: Overview 33 | C3: 1 | D3: 01. 33OVERVIEW.docx | E3: 1 | F3: =Master_List!$AW$1 -> PERPUSTAKAAN PUSAT | G3: =Master_List!$AW$2 -> 09:30 PM | H3: =Master_List!$AW$3 -> 20/07/2026 | I3: =Master_List!$AW$4 -> 28.5 | J3: =Master_List!$AW$5 -> 65 | K3: OVERVIEW FRONT (LHS) | BL3: {} | BM3: page1 | BN3: IR Image Path | BO3: =BO2 -> C:\Users\aremi\Desktop\REPORT CBM\PO TIANU JB\03. Raw Material\40. 10052026 SSU MEDINI SIGNATURE 33KV (VI)\IR | BP3: 2.jpg
A4: 2 | B4: Overview 33 | C4: 1 | D4: 01. 33OVERVIEW.docx | E4: 2 | F4: =Master_List!$AW$1 -> PERPUSTAKAAN PUSAT | G4: =Master_List!$AW$2 -> 09:30 PM | H4: =Master_List!$AW$3 -> 20/07/2026 | I4: =Master_List!$AW$4 -> 28.5 | J4: =Master_List!$AW$5 -> 65 | K4: OVERVIEW FRONT (RHS) | BL4: {} | BM4: page2 | BN4: Visual Image Path | BO4: =BO3 -> C:\Users\aremi\Desktop\REPORT CBM\PO TIANU JB\03. Raw Material\40. 10052026 SSU MEDINI SIGNATURE 33KV (VI)\IR | BP4: 3.jpg
A5: 2 | B5: Overview 33 | C5: 1 | D5: 01. 33OVERVIEW.docx | E5: 2 | F5: =Master_List!$AW$1 -> PERPUSTAKAAN PUSAT | G5: =Master_List!$AW$2 -> 09:30 PM | H5: =Master_List!$AW$3 -> 20/07/2026 | I5: =Master_List!$AW$4 -> 28.5 | J5: =Master_List!$AW$5 -> 65 | K5: OVERVIEW FRONT (RHS) | BL5: {} | BM5: page2 | BN5: IR Image Path | BO5: =BO4 -> C:\Users\aremi\Desktop\REPORT CBM\PO TIANU JB\03. Raw Material\40. 10052026 SSU MEDINI SIGNATURE 33KV (VI)\IR | BP5: 4.jpg
A6: 3 | B6: Overview 33 | C6: 1 | D6: 01. 33OVERVIEW.docx | E6: 3 | F6: =Master_List!$AW$1 -> PERPUSTAKAAN PUSAT | G6: =Master_List!$AW$2 -> 09:30 PM | H6: =Master_List!$AW$3 -> 20/07/2026 | I6: =Master_List!$AW$4 -> 28.5 | J6: =Master_List!$AW$5 -> 65 | K6: OVERVIEW REAR (LHS) | BL6: {} | BM6: page3 | BN6: Visual Image Path | BO6: =BO5 -> C:\Users\aremi\Desktop\REPORT CBM\PO TIANU JB\03. Raw Material\40. 10052026 SSU MEDINI SIGNATURE 33KV (VI)\IR | BP6: 5.jpg
A7: 3 | B7: Overview 33 | C7: 1 | D7: 01. 33OVERVIEW.docx | E7: 3 | F7: =Master_List!$AW$1 -> PERPUSTAKAAN PUSAT | G7: =Master_List!$AW$2 -> 09:30 PM | H7: =Master_List!$AW$3 -> 20/07/2026 | I7: =Master_List!$AW$4 -> 28.5 | J7: =Master_List!$AW$5 -> 65 | K7: OVERVIEW REAR (LHS) | BL7: {} | BM7: page3 | BN7: IR Image Path | BO7: =BO6 -> C:\Users\aremi\Desktop\REPORT CBM\PO TIANU JB\03. Raw Material\40. 10052026 SSU MEDINI SIGNATURE 33KV (VI)\IR | BP7: 6.jpg
A8: 4 | B8: Overview 33 | C8: 1 | D8: 01. 33OVERVIEW.docx | E8: 4 | F8: =Master_List!$AW$1 -> PERPUSTAKAAN PUSAT | G8: =Master_List!$AW$2 -> 09:30 PM | H8: =Master_List!$AW$3 -> 20/07/2026 | I8: =Master_List!$AW$4 -> 28.5 | J8: =Master_List!$AW$5 -> 65 | K8: OVERVIEW REAR (RHS) | BL8: {} | BM8: page4 | BN8: Visual Image Path | BO8: =BO7 -> C:\Users\aremi\Desktop\REPORT CBM\PO TIANU JB\03. Raw Material\40. 10052026 SSU MEDINI SIGNATURE 33KV (VI)\IR | BP8: 7.jpg
A9: 4 | B9: Overview 33 | C9: 1 | D9: 01. 33OVERVIEW.docx | E9: 4 | F9: =Master_List!$AW$1 -> PERPUSTAKAAN PUSAT | G9: =Master_List!$AW$2 -> 09:30 PM | H9: =Master_List!$AW$3 -> 20/07/2026 | I9: =Master_List!$AW$4 -> 28.5 | J9: =Master_List!$AW$5 -> 65 | K9: OVERVIEW REAR (RHS) | BL9: {} | BM9: page4 | BN9: IR Image Path | BO9: =BO8 -> C:\Users\aremi\Desktop\REPORT CBM\PO TIANU JB\03. Raw Material\40. 10052026 SSU MEDINI SIGNATURE 33KV (VI)\IR | BP9: 8.jpg
A10: 5 | B10: Overview 33 | C10: 1 | D10: 01. 33OVERVIEW.docx | E10: 5 | F10: =Master_List!$AW$1 -> PERPUSTAKAAN PUSAT | G10: =Master_List!$AW$2 -> 09:30 PM | H10: =Master_List!$AW$3 -> 20/07/2026 | I10: =Master_List!$AW$4 -> 28.5 | J10: =Master_List!$AW$5 -> 65 | K10: OVERVIEW TOP (LHS) | BL10: {} | BM10: page5 | BN10: Visual Image Path | BO10: =BO9 -> C:\Users\aremi\Desktop\REPORT CBM\PO TIANU JB\03. Raw Material\40. 10052026 SSU MEDINI SIGNATURE 33KV (VI)\IR | BP10: 9.jpg
A11: 5 | B11: Overview 33 | C11: 1 | D11: 01. 33OVERVIEW.docx | E11: 5 | F11: =Master_List!$AW$1 -> PERPUSTAKAAN PUSAT | G11: =Master_List!$AW$2 -> 09:30 PM | H11: =Master_List!$AW$3 -> 20/07/2026 | I11: =Master_List!$AW$4 -> 28.5 | J11: =Master_List!$AW$5 -> 65 | K11: OVERVIEW TOP (LHS) | BL11: {} | BM11: page5 | BN11: IR Image Path | BO11: =BO10 -> C:\Users\aremi\Desktop\REPORT CBM\PO TIANU JB\03. Raw Material\40. 10052026 SSU MEDINI SIGNATURE 33KV (VI)\IR | BP11: 10.jpg
A12: 6 | B12: Overview 33 | C12: 1 | D12: 01. 33OVERVIEW.docx | E12: 6 | F12: =Master_List!$AW$1 -> PERPUSTAKAAN PUSAT | G12: =Master_List!$AW$2 -> 09:30 PM | H12: =Master_List!$AW$3 -> 20/07/2026 | I12: =Master_List!$AW$4 -> 28.5 | J12: =Master_List!$AW$5 -> 65 | K12: OVERVIEW TOP (RHS) | BL12: {} | BM12: page6 | BN12: Visual Image Path | BO12: =BO11 -> C:\Users\aremi\Desktop\REPORT CBM\PO TIANU JB\03. Raw Material\40. 10052026 SSU MEDINI SIGNATURE 33KV (VI)\IR | BP12: 11.jpg
A13: 6 | B13: Overview 33 | C13: 1 | D13: 01. 33OVERVIEW.docx | E13: 6 | F13: =Master_List!$AW$1 -> PERPUSTAKAAN PUSAT | G13: =Master_List!$AW$2 -> 09:30 PM | H13: =Master_List!$AW$3 -> 20/07/2026 | I13: =Master_List!$AW$4 -> 28.5 | J13: =Master_List!$AW$5 -> 65 | K13: OVERVIEW TOP (RHS) | BL13: {} | BM13: page6 | BN13: IR Image Path | BO13: =BO12 -> C:\Users\aremi\Desktop\REPORT CBM\PO TIANU JB\03. Raw Material\40. 10052026 SSU MEDINI SIGNATURE 33KV (VI)\IR | BP13: 12.jpg
A14: 7 | B14: Overview 33 | C14: 1 | D14: 01. 33OVERVIEW.docx | E14: 7 | F14: =Master_List!$AW$1 -> PERPUSTAKAAN PUSAT | G14: =Master_List!$AW$2 -> 09:30 PM | H14: =Master_List!$AW$3 -> 20/07/2026 | I14: =Master_List!$AW$4 -> 28.5 | J14: =Master_List!$AW$5 -> 65 | K14: OVERVIEW BUSBAR (LHS) | BL14: {} | BM14: page7 | BN14: Visual Image Path | BO14: =BO13 -> C:\Users\aremi\Desktop\REPORT CBM\PO TIANU JB\03. Raw Material\40. 10052026 SSU MEDINI SIGNATURE 33KV (VI)\IR | BP14: 13.jpg
... A905: 452 | B905: N.E.R | C905: 13 | D905: 36. N.E.R.docx | E905: 1 | F905: =Master_List!$AW$1 -> PERPUSTAKAAN PUSAT | G905: =Master_List!$AW$2 -> 09:30 PM | H905: =Master_List!$AW$3 -> 20/07/2026 | I905: =Master_List!$AW$4 -> 28.5 | J905: =Master_List!$AW$5 -> 65 | K905: OVERVIEW | BL905: {} | BM905: page452 | BN905: IR Image Path | BO905: =BO904 -> C:\Users\aremi\Desktop\REPORT CBM\PO TIANU JB\03. Raw Material\40. 10052026 SSU MEDINI SIGNATURE 33KV (VI)\IR | BP905: 1556.jpg

Sheet Image_Mapping_VCB
A1: No | B1: Type | C1: Group | D1: Word Template | E1: Template Page No | F1: {{ substation.name_erms }} | G1: {{ substation.time }} | H1: {{ substation.date }} | I1: {{ substation.ambient }} | J1: {{ substation.humidity }} | K1: {{ swg.area }} | L1: {{ panel.linknumber }} | M1: {{ panel.name }} | N1: {{ panel.cabletype }} | O1: {{ panel.breakerstatus }} | P1: {{ panel.busbarposition }} | Q1: {{ panel.loadamp }} | R1: {{ panel.heateramp }} | S1: {{ swg.serialnumber }} | T1: {{ swg.manufacturer }} | U1: {{ swg.type }} | V1: {{ swg.rating }} | W1: {{ swg.model }} | X1: {{ tx1.manufacturer }} | Y1: {{ tx1.model }} | Z1: {{ tx1.rating }} | AA1: {{ tx1.serialnumber }} | AB1: {{ tx2.manufacturer }} | AC1: {{ tx2.model }} | AD1: {{ tx2.rating }} | AE1: {{ tx2.serialnumber }} | AF1: {{ fp1.manufacturer }} | AG1: {{ fp1.model }} | AH1: {{ fp1.rating }} | AI1: {{ fp1.serialnumber }} | AJ1: {{ fp1.labelsource }} | AK1: {{ fp2.manufacturer }} | AL1: {{ fp2.model }} | AM1: {{ fp2.rating }} | AN1: {{ fp2.serialnumber }} | AO1: {{ fp2.labelsource }} | AP1: {{ batt1.manufacturer }} | AQ1: {{ batt1.model }} | AR1: {{ batt1.serialnumber }} | AS1: {{ batt2.manufacturer }} | AT1: {{ batt2.model }} | AU1: {{ batt2.serialnumber }} | AV1: {{ batt3.manufacturer }} | AW1: {{ batt3.model }} | AX1: {{ batt3.serialnumber }} | AY1: {{ batt4.manufacturer }} | AZ1: {{ batt4.model }} | BA1: {{ batt4.serialnumber }} | BB1: {{ panel.db_level }} | BC1: {{ panel.us.char }} | BD1: Field Overrides | BE1: Output File Name | BF1: Attribute | BG1: Folder | BH1: Image File Name
A2: 1 | B2: Overview | C2: 1 | D2: 01. vcb-overview.docx | E2: 1 | F2: =Master_List!$AW$1 -> PERPUSTAKAAN PUSAT | G2: =Master_List!$AW$2 -> 09:30 PM | H2: =Master_List!$AW$3 -> 20/07/2026 | I2: =Master_List!$AW$4 -> 28.5 | J2: =Master_List!$AW$5 -> 65 | K2: OVERVIEW FRONT (LHS) | L2: =IFERROR(VLOOKUP(B2, Master_List!$A:$I, 2, FALSE), "-") -> - | M2: =IFERROR(VLOOKUP(B2, Master_List!$A:$I, 3, FALSE), "-") -> - | N2: =IFERROR(VLOOKUP(B2, Master_List!$A:$I, 4, FALSE), "-") -> - | O2: =IFERROR(VLOOKUP(B2, Master_List!$A:$I, 5, FALSE), "-") -> - | P2: =IFERROR(VLOOKUP(B2, Master_List!$A:$I, 6, FALSE), "-") -> - | Q2: =IFERROR(VLOOKUP(B2, Master_List!$A:$I, 7, FALSE), "-") -> - | R2: =IFERROR(VLOOKUP(B2, Master_List!$A:$I, 8, FALSE), "-") -> - | S2: =IFERROR(VLOOKUP(B2, Master_List!$A:$I, 9, FALSE), "-") -> - | T2: =Master_List!$AW$6 -> TOSHIBA | U2: =Master_List!$AW$7 -> MRMU | V2: =Master_List!$AW$8 -> 12kV | W2: =Master_List!$AW$9 -> 2S1F | X2: =Master_List!$AW$10 -> MTM | Y2: =Master_List!$AW$11 -> HERMETICALLY SEAL | Z2: =Master_List!$AW$12 -> 750kVA | AA2: =Master_List!$AW$13 -> 1317 | AB2: =Master_List!$AW$14 -> 0 | AC2: =Master_List!$AW$15 -> 0 | AD2: =Master_List!$AW$16 -> 0 | AE2: =Master_List!$AW$17 -> 0 | AF2: =Master_List!$AW$18 -> INDKOM | AG2: =Master_List!$AW$19 -> J-SLOTTED | AH2: =Master_List!$AW$20 -> 1600A | AI2: =Master_List!$AW$21 -> LV5080090 | AJ2: =Master_List!$AW$22 -> LVDB TX1 | AK2: =Master_List!$AW$23 -> 0 | AL2: =Master_List!$AW$24 -> 0 | AM2: =Master_List!$AW$25 -> 0 | AN2: =Master_List!$AW$26 -> 0 | AO2: =Master_List!$AW$27 -> LVDB TX2 | AP2: =Master_List!$AW$28 -> SUNPOWER TECHNOLOGIES | AQ2: =Master_List!$AW$29 -> SPS 30-10 L | AR2: =Master_List!$AW$30 -> 11193-8527 | AS2: =Master_List!$AW$31 -> 0 | AT2: =Master_List!$AW$32 -> 0 | AU2: =Master_List!$AW$33 -> 0 | AV2: =Master_List!$AW$34 -> 0 | AW2: =Master_List!$AW$35 -> 0 | AX2: =Master_List!$AW$36 -> 0 | AY2: =Master_List!$AW$37 -> 0 | AZ2: =Master_List!$AW$38 -> 0 | BA2: =Master_List!$AW$39 -> 0 | BB2: 0dB | BC2: Normal | BD2: {} | BE2: page1 | BF2: Visual Image Path | BG2: =Master_List!AZ1 -> C:\Users\aremi\Desktop\REPORT CBM\PO 42289580 - Pahang 11kV SECOND CYCLE AZZAD 2026\RAW MATERIAL\047. TNB BARU (IR+VI)\RAW DATA\IR | BH2: 1.jpg
A3: 1 | B3: Overview | C3: 1 | D3: 01. vcb-overview.docx | E3: 1 | F3: =Master_List!$AW$1 -> PERPUSTAKAAN PUSAT | G3: =Master_List!$AW$2 -> 09:30 PM | H3: =Master_List!$AW$3 -> 20/07/2026 | I3: =Master_List!$AW$4 -> 28.5 | J3: =Master_List!$AW$5 -> 65 | K3: OVERVIEW FRONT (LHS) | L3: =IFERROR(VLOOKUP(B3, Master_List!$A:$I, 2, FALSE), "-") -> - | M3: =IFERROR(VLOOKUP(B3, Master_List!$A:$I, 3, FALSE), "-") -> - | N3: =IFERROR(VLOOKUP(B3, Master_List!$A:$I, 4, FALSE), "-") -> - | O3: =IFERROR(VLOOKUP(B3, Master_List!$A:$I, 5, FALSE), "-") -> - | P3: =IFERROR(VLOOKUP(B3, Master_List!$A:$I, 6, FALSE), "-") -> - | Q3: =IFERROR(VLOOKUP(B3, Master_List!$A:$I, 7, FALSE), "-") -> - | R3: =IFERROR(VLOOKUP(B3, Master_List!$A:$I, 8, FALSE), "-") -> - | S3: =IFERROR(VLOOKUP(B3, Master_List!$A:$I, 9, FALSE), "-") -> - | T3: =Master_List!$AW$6 -> TOSHIBA | U3: =Master_List!$AW$7 -> MRMU | V3: =Master_List!$AW$8 -> 12kV | W3: =Master_List!$AW$9 -> 2S1F | X3: =Master_List!$AW$10 -> MTM | Y3: =Master_List!$AW$11 -> HERMETICALLY SEAL | Z3: =Master_List!$AW$12 -> 750kVA | AA3: =Master_List!$AW$13 -> 1317 | AB3: =Master_List!$AW$14 -> 0 | AC3: =Master_List!$AW$15 -> 0 | AD3: =Master_List!$AW$16 -> 0 | AE3: =Master_List!$AW$17 -> 0 | AF3: =Master_List!$AW$18 -> INDKOM | AG3: =Master_List!$AW$19 -> J-SLOTTED | AH3: =Master_List!$AW$20 -> 1600A | AI3: =Master_List!$AW$21 -> LV5080090 | AJ3: =Master_List!$AW$22 -> LVDB TX1 | AK3: =Master_List!$AW$23 -> 0 | AL3: =Master_List!$AW$24 -> 0 | AM3: =Master_List!$AW$25 -> 0 | AN3: =Master_List!$AW$26 -> 0 | AO3: =Master_List!$AW$27 -> LVDB TX2 | AP3: =Master_List!$AW$28 -> SUNPOWER TECHNOLOGIES | AQ3: =Master_List!$AW$29 -> SPS 30-10 L | AR3: =Master_List!$AW$30 -> 11193-8527 | AS3: =Master_List!$AW$31 -> 0 | AT3: =Master_List!$AW$32 -> 0 | AU3: =Master_List!$AW$33 -> 0 | AV3: =Master_List!$AW$34 -> 0 | AW3: =Master_List!$AW$35 -> 0 | AX3: =Master_List!$AW$36 -> 0 | AY3: =Master_List!$AW$37 -> 0 | AZ3: =Master_List!$AW$38 -> 0 | BA3: =Master_List!$AW$39 -> 0 | BB3: 0dB | BC3: Normal | BD3: {} | BE3: page1 | BF3: IR Image Path | BG3: =BG2 -> C:\Users\aremi\Desktop\REPORT CBM\PO 42289580 - Pahang 11kV SECOND CYCLE AZZAD 2026\RAW MATERIAL\047. TNB BARU (IR+VI)\RAW DATA\IR | BH3: 2.jpg
A4: 2 | B4: Overview | C4: 1 | D4: 01. vcb-overview.docx | E4: 2 | F4: =Master_List!$AW$1 -> PERPUSTAKAAN PUSAT | G4: =Master_List!$AW$2 -> 09:30 PM | H4: =Master_List!$AW$3 -> 20/07/2026 | I4: =Master_List!$AW$4 -> 28.5 | J4: =Master_List!$AW$5 -> 65 | K4: OVERVIEW FRONT (RHS) | L4: =IFERROR(VLOOKUP(B4, Master_List!$A:$I, 2, FALSE), "-") -> - | M4: =IFERROR(VLOOKUP(B4, Master_List!$A:$I, 3, FALSE), "-") -> - | N4: =IFERROR(VLOOKUP(B4, Master_List!$A:$I, 4, FALSE), "-") -> - | O4: =IFERROR(VLOOKUP(B4, Master_List!$A:$I, 5, FALSE), "-") -> - | P4: =IFERROR(VLOOKUP(B4, Master_List!$A:$I, 6, FALSE), "-") -> - | Q4: =IFERROR(VLOOKUP(B4, Master_List!$A:$I, 7, FALSE), "-") -> - | R4: =IFERROR(VLOOKUP(B4, Master_List!$A:$I, 8, FALSE), "-") -> - | S4: =IFERROR(VLOOKUP(B4, Master_List!$A:$I, 9, FALSE), "-") -> - | T4: =Master_List!$AW$6 -> TOSHIBA | U4: =Master_List!$AW$7 -> MRMU | V4: =Master_List!$AW$8 -> 12kV | W4: =Master_List!$AW$9 -> 2S1F | X4: =Master_List!$AW$10 -> MTM | Y4: =Master_List!$AW$11 -> HERMETICALLY SEAL | Z4: =Master_List!$AW$12 -> 750kVA | AA4: =Master_List!$AW$13 -> 1317 | AB4: =Master_List!$AW$14 -> 0 | AC4: =Master_List!$AW$15 -> 0 | AD4: =Master_List!$AW$16 -> 0 | AE4: =Master_List!$AW$17 -> 0 | AF4: =Master_List!$AW$18 -> INDKOM | AG4: =Master_List!$AW$19 -> J-SLOTTED | AH4: =Master_List!$AW$20 -> 1600A | AI4: =Master_List!$AW$21 -> LV5080090 | AJ4: =Master_List!$AW$22 -> LVDB TX1 | AK4: =Master_List!$AW$23 -> 0 | AL4: =Master_List!$AW$24 -> 0 | AM4: =Master_List!$AW$25 -> 0 | AN4: =Master_List!$AW$26 -> 0 | AO4: =Master_List!$AW$27 -> LVDB TX2 | AP4: =Master_List!$AW$28 -> SUNPOWER TECHNOLOGIES | AQ4: =Master_List!$AW$29 -> SPS 30-10 L | AR4: =Master_List!$AW$30 -> 11193-8527 | AS4: =Master_List!$AW$31 -> 0 | AT4: =Master_List!$AW$32 -> 0 | AU4: =Master_List!$AW$33 -> 0 | AV4: =Master_List!$AW$34 -> 0 | AW4: =Master_List!$AW$35 -> 0 | AX4: =Master_List!$AW$36 -> 0 | AY4: =Master_List!$AW$37 -> 0 | AZ4: =Master_List!$AW$38 -> 0 | BA4: =Master_List!$AW$39 -> 0 | BB4: 0dB | BC4: Normal | BD4: {} | BE4: page2 | BF4: Visual Image Path | BG4: =BG3 -> C:\Users\aremi\Desktop\REPORT CBM\PO 42289580 - Pahang 11kV SECOND CYCLE AZZAD 2026\RAW MATERIAL\047. TNB BARU (IR+VI)\RAW DATA\IR | BH4: 3.jpg
A5: 2 | B5: Overview | C5: 1 | D5: 01. vcb-overview.docx | E5: 2 | F5: =Master_List!$AW$1 -> PERPUSTAKAAN PUSAT | G5: =Master_List!$AW$2 -> 09:30 PM | H5: =Master_List!$AW$3 -> 20/07/2026 | I5: =Master_List!$AW$4 -> 28.5 | J5: =Master_List!$AW$5 -> 65 | K5: OVERVIEW FRONT (RHS) | L5: =IFERROR(VLOOKUP(B5, Master_List!$A:$I, 2, FALSE), "-") -> - | M5: =IFERROR(VLOOKUP(B5, Master_List!$A:$I, 3, FALSE), "-") -> - | N5: =IFERROR(VLOOKUP(B5, Master_List!$A:$I, 4, FALSE), "-") -> - | O5: =IFERROR(VLOOKUP(B5, Master_List!$A:$I, 5, FALSE), "-") -> - | P5: =IFERROR(VLOOKUP(B5, Master_List!$A:$I, 6, FALSE), "-") -> - | Q5: =IFERROR(VLOOKUP(B5, Master_List!$A:$I, 7, FALSE), "-") -> - | R5: =IFERROR(VLOOKUP(B5, Master_List!$A:$I, 8, FALSE), "-") -> - | S5: =IFERROR(VLOOKUP(B5, Master_List!$A:$I, 9, FALSE), "-") -> - | T5: =Master_List!$AW$6 -> TOSHIBA | U5: =Master_List!$AW$7 -> MRMU | V5: =Master_List!$AW$8 -> 12kV | W5: =Master_List!$AW$9 -> 2S1F | X5: =Master_List!$AW$10 -> MTM | Y5: =Master_List!$AW$11 -> HERMETICALLY SEAL | Z5: =Master_List!$AW$12 -> 750kVA | AA5: =Master_List!$AW$13 -> 1317 | AB5: =Master_List!$AW$14 -> 0 | AC5: =Master_List!$AW$15 -> 0 | AD5: =Master_List!$AW$16 -> 0 | AE5: =Master_List!$AW$17 -> 0 | AF5: =Master_List!$AW$18 -> INDKOM | AG5: =Master_List!$AW$19 -> J-SLOTTED | AH5: =Master_List!$AW$20 -> 1600A | AI5: =Master_List!$AW$21 -> LV5080090 | AJ5: =Master_List!$AW$22 -> LVDB TX1 | AK5: =Master_List!$AW$23 -> 0 | AL5: =Master_List!$AW$24 -> 0 | AM5: =Master_List!$AW$25 -> 0 | AN5: =Master_List!$AW$26 -> 0 | AO5: =Master_List!$AW$27 -> LVDB TX2 | AP5: =Master_List!$AW$28 -> SUNPOWER TECHNOLOGIES | AQ5: =Master_List!$AW$29 -> SPS 30-10 L | AR5: =Master_List!$AW$30 -> 11193-8527 | AS5: =Master_List!$AW$31 -> 0 | AT5: =Master_List!$AW$32 -> 0 | AU5: =Master_List!$AW$33 -> 0 | AV5: =Master_List!$AW$34 -> 0 | AW5: =Master_List!$AW$35 -> 0 | AX5: =Master_List!$AW$36 -> 0 | AY5: =Master_List!$AW$37 -> 0 | AZ5: =Master_List!$AW$38 -> 0 | BA5: =Master_List!$AW$39 -> 0 | BB5: 0dB | BC5: Normal | BD5: {} | BE5: page2 | BF5: IR Image Path | BG5: =BG4 -> C:\Users\aremi\Desktop\REPORT CBM\PO 42289580 - Pahang 11kV SECOND CYCLE AZZAD 2026\RAW MATERIAL\047. TNB BARU (IR+VI)\RAW DATA\IR | BH5: 4.jpg
A6: 3 | B6: Overview | C6: 1 | D6: 01. vcb-overview.docx | E6: 3 | F6: =Master_List!$AW$1 -> PERPUSTAKAAN PUSAT | G6: =Master_List!$AW$2 -> 09:30 PM | H6: =Master_List!$AW$3 -> 20/07/2026 | I6: =Master_List!$AW$4 -> 28.5 | J6: =Master_List!$AW$5 -> 65 | K6: OVERVIEW REAR (LHS) | L6: =IFERROR(VLOOKUP(B6, Master_List!$A:$I, 2, FALSE), "-") -> - | M6: =IFERROR(VLOOKUP(B6, Master_List!$A:$I, 3, FALSE), "-") -> - | N6: =IFERROR(VLOOKUP(B6, Master_List!$A:$I, 4, FALSE), "-") -> - | O6: =IFERROR(VLOOKUP(B6, Master_List!$A:$I, 5, FALSE), "-") -> - | P6: =IFERROR(VLOOKUP(B6, Master_List!$A:$I, 6, FALSE), "-") -> - | Q6: =IFERROR(VLOOKUP(B6, Master_List!$A:$I, 7, FALSE), "-") -> - | R6: =IFERROR(VLOOKUP(B6, Master_List!$A:$I, 8, FALSE), "-") -> - | S6: =IFERROR(VLOOKUP(B6, Master_List!$A:$I, 9, FALSE), "-") -> - | T6: =Master_List!$AW$6 -> TOSHIBA | U6: =Master_List!$AW$7 -> MRMU | V6: =Master_List!$AW$8 -> 12kV | W6: =Master_List!$AW$9 -> 2S1F | X6: =Master_List!$AW$10 -> MTM | Y6: =Master_List!$AW$11 -> HERMETICALLY SEAL | Z6: =Master_List!$AW$12 -> 750kVA | AA6: =Master_List!$AW$13 -> 1317 | AB6: =Master_List!$AW$14 -> 0 | AC6: =Master_List!$AW$15 -> 0 | AD6: =Master_List!$AW$16 -> 0 | AE6: =Master_List!$AW$17 -> 0 | AF6: =Master_List!$AW$18 -> INDKOM | AG6: =Master_List!$AW$19 -> J-SLOTTED | AH6: =Master_List!$AW$20 -> 1600A | AI6: =Master_List!$AW$21 -> LV5080090 | AJ6: =Master_List!$AW$22 -> LVDB TX1 | AK6: =Master_List!$AW$23 -> 0 | AL6: =Master_List!$AW$24 -> 0 | AM6: =Master_List!$AW$25 -> 0 | AN6: =Master_List!$AW$26 -> 0 | AO6: =Master_List!$AW$27 -> LVDB TX2 | AP6: =Master_List!$AW$28 -> SUNPOWER TECHNOLOGIES | AQ6: =Master_List!$AW$29 -> SPS 30-10 L | AR6: =Master_List!$AW$30 -> 11193-8527 | AS6: =Master_List!$AW$31 -> 0 | AT6: =Master_List!$AW$32 -> 0 | AU6: =Master_List!$AW$33 -> 0 | AV6: =Master_List!$AW$34 -> 0 | AW6: =Master_List!$AW$35 -> 0 | AX6: =Master_List!$AW$36 -> 0 | AY6: =Master_List!$AW$37 -> 0 | AZ6: =Master_List!$AW$38 -> 0 | BA6: =Master_List!$AW$39 -> 0 | BB6: 0dB | BC6: Normal | BD6: {} | BE6: page3 | BF6: Visual Image Path | BG6: =BG5 -> C:\Users\aremi\Desktop\REPORT CBM\PO 42289580 - Pahang 11kV SECOND CYCLE AZZAD 2026\RAW MATERIAL\047. TNB BARU (IR+VI)\RAW DATA\IR | BH6: 5.jpg
A7: 3 | B7: Overview | C7: 1 | D7: 01. vcb-overview.docx | E7: 3 | F7: =Master_List!$AW$1 -> PERPUSTAKAAN PUSAT | G7: =Master_List!$AW$2 -> 09:30 PM | H7: =Master_List!$AW$3 -> 20/07/2026 | I7: =Master_List!$AW$4 -> 28.5 | J7: =Master_List!$AW$5 -> 65 | K7: OVERVIEW REAR (LHS) | L7: =IFERROR(VLOOKUP(B7, Master_List!$A:$I, 2, FALSE), "-") -> - | M7: =IFERROR(VLOOKUP(B7, Master_List!$A:$I, 3, FALSE), "-") -> - | N7: =IFERROR(VLOOKUP(B7, Master_List!$A:$I, 4, FALSE), "-") -> - | O7: =IFERROR(VLOOKUP(B7, Master_List!$A:$I, 5, FALSE), "-") -> - | P7: =IFERROR(VLOOKUP(B7, Master_List!$A:$I, 6, FALSE), "-") -> - | Q7: =IFERROR(VLOOKUP(B7, Master_List!$A:$I, 7, FALSE), "-") -> - | R7: =IFERROR(VLOOKUP(B7, Master_List!$A:$I, 8, FALSE), "-") -> - | S7: =IFERROR(VLOOKUP(B7, Master_List!$A:$I, 9, FALSE), "-") -> - | T7: =Master_List!$AW$6 -> TOSHIBA | U7: =Master_List!$AW$7 -> MRMU | V7: =Master_List!$AW$8 -> 12kV | W7: =Master_List!$AW$9 -> 2S1F | X7: =Master_List!$AW$10 -> MTM | Y7: =Master_List!$AW$11 -> HERMETICALLY SEAL | Z7: =Master_List!$AW$12 -> 750kVA | AA7: =Master_List!$AW$13 -> 1317 | AB7: =Master_List!$AW$14 -> 0 | AC7: =Master_List!$AW$15 -> 0 | AD7: =Master_List!$AW$16 -> 0 | AE7: =Master_List!$AW$17 -> 0 | AF7: =Master_List!$AW$18 -> INDKOM | AG7: =Master_List!$AW$19 -> J-SLOTTED | AH7: =Master_List!$AW$20 -> 1600A | AI7: =Master_List!$AW$21 -> LV5080090 | AJ7: =Master_List!$AW$22 -> LVDB TX1 | AK7: =Master_List!$AW$23 -> 0 | AL7: =Master_List!$AW$24 -> 0 | AM7: =Master_List!$AW$25 -> 0 | AN7: =Master_List!$AW$26 -> 0 | AO7: =Master_List!$AW$27 -> LVDB TX2 | AP7: =Master_List!$AW$28 -> SUNPOWER TECHNOLOGIES | AQ7: =Master_List!$AW$29 -> SPS 30-10 L | AR7: =Master_List!$AW$30 -> 11193-8527 | AS7: =Master_List!$AW$31 -> 0 | AT7: =Master_List!$AW$32 -> 0 | AU7: =Master_List!$AW$33 -> 0 | AV7: =Master_List!$AW$34 -> 0 | AW7: =Master_List!$AW$35 -> 0 | AX7: =Master_List!$AW$36 -> 0 | AY7: =Master_List!$AW$37 -> 0 | AZ7: =Master_List!$AW$38 -> 0 | BA7: =Master_List!$AW$39 -> 0 | BB7: 0dB | BC7: Normal | BD7: {} | BE7: page3 | BF7: IR Image Path | BG7: =BG6 -> C:\Users\aremi\Desktop\REPORT CBM\PO 42289580 - Pahang 11kV SECOND CYCLE AZZAD 2026\RAW MATERIAL\047. TNB BARU (IR+VI)\RAW DATA\IR | BH7: 6.jpg
A8: 4 | B8: Overview | C8: 1 | D8: 01. vcb-overview.docx | E8: 4 | F8: =Master_List!$AW$1 -> PERPUSTAKAAN PUSAT | G8: =Master_List!$AW$2 -> 09:30 PM | H8: =Master_List!$AW$3 -> 20/07/2026 | I8: =Master_List!$AW$4 -> 28.5 | J8: =Master_List!$AW$5 -> 65 | K8: OVERVIEW REAR (RHS) | L8: =IFERROR(VLOOKUP(B8, Master_List!$A:$I, 2, FALSE), "-") -> - | M8: =IFERROR(VLOOKUP(B8, Master_List!$A:$I, 3, FALSE), "-") -> - | N8: =IFERROR(VLOOKUP(B8, Master_List!$A:$I, 4, FALSE), "-") -> - | O8: =IFERROR(VLOOKUP(B8, Master_List!$A:$I, 5, FALSE), "-") -> - | P8: =IFERROR(VLOOKUP(B8, Master_List!$A:$I, 6, FALSE), "-") -> - | Q8: =IFERROR(VLOOKUP(B8, Master_List!$A:$I, 7, FALSE), "-") -> - | R8: =IFERROR(VLOOKUP(B8, Master_List!$A:$I, 8, FALSE), "-") -> - | S8: =IFERROR(VLOOKUP(B8, Master_List!$A:$I, 9, FALSE), "-") -> - | T8: =Master_List!$AW$6 -> TOSHIBA | U8: =Master_List!$AW$7 -> MRMU | V8: =Master_List!$AW$8 -> 12kV | W8: =Master_List!$AW$9 -> 2S1F | X8: =Master_List!$AW$10 -> MTM | Y8: =Master_List!$AW$11 -> HERMETICALLY SEAL | Z8: =Master_List!$AW$12 -> 750kVA | AA8: =Master_List!$AW$13 -> 1317 | AB8: =Master_List!$AW$14 -> 0 | AC8: =Master_List!$AW$15 -> 0 | AD8: =Master_List!$AW$16 -> 0 | AE8: =Master_List!$AW$17 -> 0 | AF8: =Master_List!$AW$18 -> INDKOM | AG8: =Master_List!$AW$19 -> J-SLOTTED | AH8: =Master_List!$AW$20 -> 1600A | AI8: =Master_List!$AW$21 -> LV5080090 | AJ8: =Master_List!$AW$22 -> LVDB TX1 | AK8: =Master_List!$AW$23 -> 0 | AL8: =Master_List!$AW$24 -> 0 | AM8: =Master_List!$AW$25 -> 0 | AN8: =Master_List!$AW$26 -> 0 | AO8: =Master_List!$AW$27 -> LVDB TX2 | AP8: =Master_List!$AW$28 -> SUNPOWER TECHNOLOGIES | AQ8: =Master_List!$AW$29 -> SPS 30-10 L | AR8: =Master_List!$AW$30 -> 11193-8527 | AS8: =Master_List!$AW$31 -> 0 | AT8: =Master_List!$AW$32 -> 0 | AU8: =Master_List!$AW$33 -> 0 | AV8: =Master_List!$AW$34 -> 0 | AW8: =Master_List!$AW$35 -> 0 | AX8: =Master_List!$AW$36 -> 0 | AY8: =Master_List!$AW$37 -> 0 | AZ8: =Master_List!$AW$38 -> 0 | BA8: =Master_List!$AW$39 -> 0 | BB8: 0dB | BC8: Normal | BD8: {} | BE8: page4 | BF8: Visual Image Path | BG8: =BG7 -> C:\Users\aremi\Desktop\REPORT CBM\PO 42289580 - Pahang 11kV SECOND CYCLE AZZAD 2026\RAW MATERIAL\047. TNB BARU (IR+VI)\RAW DATA\IR | BH8: 7.jpg
A9: 4 | B9: Overview | C9: 1 | D9: 01. vcb-overview.docx | E9: 4 | F9: =Master_List!$AW$1 -> PERPUSTAKAAN PUSAT | G9: =Master_List!$AW$2 -> 09:30 PM | H9: =Master_List!$AW$3 -> 20/07/2026 | I9: =Master_List!$AW$4 -> 28.5 | J9: =Master_List!$AW$5 -> 65 | K9: OVERVIEW REAR (RHS) | L9: =IFERROR(VLOOKUP(B9, Master_List!$A:$I, 2, FALSE), "-") -> - | M9: =IFERROR(VLOOKUP(B9, Master_List!$A:$I, 3, FALSE), "-") -> - | N9: =IFERROR(VLOOKUP(B9, Master_List!$A:$I, 4, FALSE), "-") -> - | O9: =IFERROR(VLOOKUP(B9, Master_List!$A:$I, 5, FALSE), "-") -> - | P9: =IFERROR(VLOOKUP(B9, Master_List!$A:$I, 6, FALSE), "-") -> - | Q9: =IFERROR(VLOOKUP(B9, Master_List!$A:$I, 7, FALSE), "-") -> - | R9: =IFERROR(VLOOKUP(B9, Master_List!$A:$I, 8, FALSE), "-") -> - | S9: =IFERROR(VLOOKUP(B9, Master_List!$A:$I, 9, FALSE), "-") -> - | T9: =Master_List!$AW$6 -> TOSHIBA | U9: =Master_List!$AW$7 -> MRMU | V9: =Master_List!$AW$8 -> 12kV | W9: =Master_List!$AW$9 -> 2S1F | X9: =Master_List!$AW$10 -> MTM | Y9: =Master_List!$AW$11 -> HERMETICALLY SEAL | Z9: =Master_List!$AW$12 -> 750kVA | AA9: =Master_List!$AW$13 -> 1317 | AB9: =Master_List!$AW$14 -> 0 | AC9: =Master_List!$AW$15 -> 0 | AD9: =Master_List!$AW$16 -> 0 | AE9: =Master_List!$AW$17 -> 0 | AF9: =Master_List!$AW$18 -> INDKOM | AG9: =Master_List!$AW$19 -> J-SLOTTED | AH9: =Master_List!$AW$20 -> 1600A | AI9: =Master_List!$AW$21 -> LV5080090 | AJ9: =Master_List!$AW$22 -> LVDB TX1 | AK9: =Master_List!$AW$23 -> 0 | AL9: =Master_List!$AW$24 -> 0 | AM9: =Master_List!$AW$25 -> 0 | AN9: =Master_List!$AW$26 -> 0 | AO9: =Master_List!$AW$27 -> LVDB TX2 | AP9: =Master_List!$AW$28 -> SUNPOWER TECHNOLOGIES | AQ9: =Master_List!$AW$29 -> SPS 30-10 L | AR9: =Master_List!$AW$30 -> 11193-8527 | AS9: =Master_List!$AW$31 -> 0 | AT9: =Master_List!$AW$32 -> 0 | AU9: =Master_List!$AW$33 -> 0 | AV9: =Master_List!$AW$34 -> 0 | AW9: =Master_List!$AW$35 -> 0 | AX9: =Master_List!$AW$36 -> 0 | AY9: =Master_List!$AW$37 -> 0 | AZ9: =Master_List!$AW$38 -> 0 | BA9: =Master_List!$AW$39 -> 0 | BB9: 0dB | BC9: Normal | BD9: {} | BE9: page4 | BF9: IR Image Path | BG9: =BG8 -> C:\Users\aremi\Desktop\REPORT CBM\PO 42289580 - Pahang 11kV SECOND CYCLE AZZAD 2026\RAW MATERIAL\047. TNB BARU (IR+VI)\RAW DATA\IR | BH9: 8.jpg
A10: 5 | B10: Overview | C10: 1 | D10: 01. vcb-overview.docx | E10: 5 | F10: =Master_List!$AW$1 -> PERPUSTAKAAN PUSAT | G10: =Master_List!$AW$2 -> 09:30 PM | H10: =Master_List!$AW$3 -> 20/07/2026 | I10: =Master_List!$AW$4 -> 28.5 | J10: =Master_List!$AW$5 -> 65 | K10: OVERVIEW TOP (LHS) | L10: =IFERROR(VLOOKUP(B10, Master_List!$A:$I, 2, FALSE), "-") -> - | M10: =IFERROR(VLOOKUP(B10, Master_List!$A:$I, 3, FALSE), "-") -> - | N10: =IFERROR(VLOOKUP(B10, Master_List!$A:$I, 4, FALSE), "-") -> - | O10: =IFERROR(VLOOKUP(B10, Master_List!$A:$I, 5, FALSE), "-") -> - | P10: =IFERROR(VLOOKUP(B10, Master_List!$A:$I, 6, FALSE), "-") -> - | Q10: =IFERROR(VLOOKUP(B10, Master_List!$A:$I, 7, FALSE), "-") -> - | R10: =IFERROR(VLOOKUP(B10, Master_List!$A:$I, 8, FALSE), "-") -> - | S10: =IFERROR(VLOOKUP(B10, Master_List!$A:$I, 9, FALSE), "-") -> - | T10: =Master_List!$AW$6 -> TOSHIBA | U10: =Master_List!$AW$7 -> MRMU | V10: =Master_List!$AW$8 -> 12kV | W10: =Master_List!$AW$9 -> 2S1F | X10: =Master_List!$AW$10 -> MTM | Y10: =Master_List!$AW$11 -> HERMETICALLY SEAL | Z10: =Master_List!$AW$12 -> 750kVA | AA10: =Master_List!$AW$13 -> 1317 | AB10: =Master_List!$AW$14 -> 0 | AC10: =Master_List!$AW$15 -> 0 | AD10: =Master_List!$AW$16 -> 0 | AE10: =Master_List!$AW$17 -> 0 | AF10: =Master_List!$AW$18 -> INDKOM | AG10: =Master_List!$AW$19 -> J-SLOTTED | AH10: =Master_List!$AW$20 -> 1600A | AI10: =Master_List!$AW$21 -> LV5080090 | AJ10: =Master_List!$AW$22 -> LVDB TX1 | AK10: =Master_List!$AW$23 -> 0 | AL10: =Master_List!$AW$24 -> 0 | AM10: =Master_List!$AW$25 -> 0 | AN10: =Master_List!$AW$26 -> 0 | AO10: =Master_List!$AW$27 -> LVDB TX2 | AP10: =Master_List!$AW$28 -> SUNPOWER TECHNOLOGIES | AQ10: =Master_List!$AW$29 -> SPS 30-10 L | AR10: =Master_List!$AW$30 -> 11193-8527 | AS10: =Master_List!$AW$31 -> 0 | AT10: =Master_List!$AW$32 -> 0 | AU10: =Master_List!$AW$33 -> 0 | AV10: =Master_List!$AW$34 -> 0 | AW10: =Master_List!$AW$35 -> 0 | AX10: =Master_List!$AW$36 -> 0 | AY10: =Master_List!$AW$37 -> 0 | AZ10: =Master_List!$AW$38 -> 0 | BA10: =Master_List!$AW$39 -> 0 | BB10: 0dB | BC10: Normal | BD10: {} | BE10: page5 | BF10: Visual Image Path | BG10: =BG9 -> C:\Users\aremi\Desktop\REPORT CBM\PO 42289580 - Pahang 11kV SECOND CYCLE AZZAD 2026\RAW MATERIAL\047. TNB BARU (IR+VI)\RAW DATA\IR | BH10: 9.jpg
A11: 5 | B11: Overview | C11: 1 | D11: 01. vcb-overview.docx | E11: 5 | F11: =Master_List!$AW$1 -> PERPUSTAKAAN PUSAT | G11: =Master_List!$AW$2 -> 09:30 PM | H11: =Master_List!$AW$3 -> 20/07/2026 | I11: =Master_List!$AW$4 -> 28.5 | J11: =Master_List!$AW$5 -> 65 | K11: OVERVIEW TOP (LHS) | L11: =IFERROR(VLOOKUP(B11, Master_List!$A:$I, 2, FALSE), "-") -> - | M11: =IFERROR(VLOOKUP(B11, Master_List!$A:$I, 3, FALSE), "-") -> - | N11: =IFERROR(VLOOKUP(B11, Master_List!$A:$I, 4, FALSE), "-") -> - | O11: =IFERROR(VLOOKUP(B11, Master_List!$A:$I, 5, FALSE), "-") -> - | P11: =IFERROR(VLOOKUP(B11, Master_List!$A:$I, 6, FALSE), "-") -> - | Q11: =IFERROR(VLOOKUP(B11, Master_List!$A:$I, 7, FALSE), "-") -> - | R11: =IFERROR(VLOOKUP(B11, Master_List!$A:$I, 8, FALSE), "-") -> - | S11: =IFERROR(VLOOKUP(B11, Master_List!$A:$I, 9, FALSE), "-") -> - | T11: =Master_List!$AW$6 -> TOSHIBA | U11: =Master_List!$AW$7 -> MRMU | V11: =Master_List!$AW$8 -> 12kV | W11: =Master_List!$AW$9 -> 2S1F | X11: =Master_List!$AW$10 -> MTM | Y11: =Master_List!$AW$11 -> HERMETICALLY SEAL | Z11: =Master_List!$AW$12 -> 750kVA | AA11: =Master_List!$AW$13 -> 1317 | AB11: =Master_List!$AW$14 -> 0 | AC11: =Master_List!$AW$15 -> 0 | AD11: =Master_List!$AW$16 -> 0 | AE11: =Master_List!$AW$17 -> 0 | AF11: =Master_List!$AW$18 -> INDKOM | AG11: =Master_List!$AW$19 -> J-SLOTTED | AH11: =Master_List!$AW$20 -> 1600A | AI11: =Master_List!$AW$21 -> LV5080090 | AJ11: =Master_List!$AW$22 -> LVDB TX1 | AK11: =Master_List!$AW$23 -> 0 | AL11: =Master_List!$AW$24 -> 0 | AM11: =Master_List!$AW$25 -> 0 | AN11: =Master_List!$AW$26 -> 0 | AO11: =Master_List!$AW$27 -> LVDB TX2 | AP11: =Master_List!$AW$28 -> SUNPOWER TECHNOLOGIES | AQ11: =Master_List!$AW$29 -> SPS 30-10 L | AR11: =Master_List!$AW$30 -> 11193-8527 | AS11: =Master_List!$AW$31 -> 0 | AT11: =Master_List!$AW$32 -> 0 | AU11: =Master_List!$AW$33 -> 0 | AV11: =Master_List!$AW$34 -> 0 | AW11: =Master_List!$AW$35 -> 0 | AX11: =Master_List!$AW$36 -> 0 | AY11: =Master_List!$AW$37 -> 0 | AZ11: =Master_List!$AW$38 -> 0 | BA11: =Master_List!$AW$39 -> 0 | BB11: 0dB | BC11: Normal | BD11: {} | BE11: page5 | BF11: IR Image Path | BG11: =BG10 -> C:\Users\aremi\Desktop\REPORT CBM\PO 42289580 - Pahang 11kV SECOND CYCLE AZZAD 2026\RAW MATERIAL\047. TNB BARU (IR+VI)\RAW DATA\IR | BH11: 10.jpg
A12: 6 | B12: Overview | C12: 1 | D12: 01. vcb-overview.docx | E12: 6 | F12: =Master_List!$AW$1 -> PERPUSTAKAAN PUSAT | G12: =Master_List!$AW$2 -> 09:30 PM | H12: =Master_List!$AW$3 -> 20/07/2026 | I12: =Master_List!$AW$4 -> 28.5 | J12: =Master_List!$AW$5 -> 65 | K12: OVERVIEW TOP (RHS) | L12: =IFERROR(VLOOKUP(B12, Master_List!$A:$I, 2, FALSE), "-") -> - | M12: =IFERROR(VLOOKUP(B12, Master_List!$A:$I, 3, FALSE), "-") -> - | N12: =IFERROR(VLOOKUP(B12, Master_List!$A:$I, 4, FALSE), "-") -> - | O12: =IFERROR(VLOOKUP(B12, Master_List!$A:$I, 5, FALSE), "-") -> - | P12: =IFERROR(VLOOKUP(B12, Master_List!$A:$I, 6, FALSE), "-") -> - | Q12: =IFERROR(VLOOKUP(B12, Master_List!$A:$I, 7, FALSE), "-") -> - | R12: =IFERROR(VLOOKUP(B12, Master_List!$A:$I, 8, FALSE), "-") -> - | S12: =IFERROR(VLOOKUP(B12, Master_List!$A:$I, 9, FALSE), "-") -> - | T12: =Master_List!$AW$6 -> TOSHIBA | U12: =Master_List!$AW$7 -> MRMU | V12: =Master_List!$AW$8 -> 12kV | W12: =Master_List!$AW$9 -> 2S1F | X12: =Master_List!$AW$10 -> MTM | Y12: =Master_List!$AW$11 -> HERMETICALLY SEAL | Z12: =Master_List!$AW$12 -> 750kVA | AA12: =Master_List!$AW$13 -> 1317 | AB12: =Master_List!$AW$14 -> 0 | AC12: =Master_List!$AW$15 -> 0 | AD12: =Master_List!$AW$16 -> 0 | AE12: =Master_List!$AW$17 -> 0 | AF12: =Master_List!$AW$18 -> INDKOM | AG12: =Master_List!$AW$19 -> J-SLOTTED | AH12: =Master_List!$AW$20 -> 1600A | AI12: =Master_List!$AW$21 -> LV5080090 | AJ12: =Master_List!$AW$22 -> LVDB TX1 | AK12: =Master_List!$AW$23 -> 0 | AL12: =Master_List!$AW$24 -> 0 | AM12: =Master_List!$AW$25 -> 0 | AN12: =Master_List!$AW$26 -> 0 | AO12: =Master_List!$AW$27 -> LVDB TX2 | AP12: =Master_List!$AW$28 -> SUNPOWER TECHNOLOGIES | AQ12: =Master_List!$AW$29 -> SPS 30-10 L | AR12: =Master_List!$AW$30 -> 11193-8527 | AS12: =Master_List!$AW$31 -> 0 | AT12: =Master_List!$AW$32 -> 0 | AU12: =Master_List!$AW$33 -> 0 | AV12: =Master_List!$AW$34 -> 0 | AW12: =Master_List!$AW$35 -> 0 | AX12: =Master_List!$AW$36 -> 0 | AY12: =Master_List!$AW$37 -> 0 | AZ12: =Master_List!$AW$38 -> 0 | BA12: =Master_List!$AW$39 -> 0 | BB12: 0dB | BC12: Normal | BD12: {} | BE12: page6 | BF12: Visual Image Path | BG12: =BG11 -> C:\Users\aremi\Desktop\REPORT CBM\PO 42289580 - Pahang 11kV SECOND CYCLE AZZAD 2026\RAW MATERIAL\047. TNB BARU (IR+VI)\RAW DATA\IR | BH12: 11.jpg
